<?xml version="1.0" ?>
<!-- =================================================================================== -->
<!-- |    This document was autogenerated by xacro from gp25_12.xacro                  | -->
<!-- |    EDITING THIS FILE BY HAND IS NOT RECOMMENDED                                 | -->
<!-- =================================================================================== -->
<robot name="motoman_gp25_12">
  <!-- link list -->
  <link name="base_link">
    <visual>
      <geometry>
        <mesh filename="package://motoman_gp25_support/meshes/gp25/visual/base_link.dae"/>
      </geometry>
      <material name="">
        <color rgba="0.12941176470588237 0.14901960784313725 0.7490196078431373 1.0"/>
      </material>
    </visual>
    <collision>
      <geometry>
        <mesh filename="package://motoman_gp25_support/meshes/gp25/collision/base_link.stl"/>
      </geometry>
    </collision>
  </link>
  <link name="link_1_s">
    <visual>
      <geometry>
        <mesh filename="package://motoman_gp25_support/meshes/gp25/visual/link_1_s.dae"/>
      </geometry>
      <material name="">
        <color rgba="0.12941176470588237 0.14901960784313725 0.7490196078431373 1.0"/>
      </material>
    </visual>
    <collision>
      <geometry>
        <mesh filename="package://motoman_gp25_support/meshes/gp25/collision/link_1_s.stl"/>
      </geometry>
    </collision>
  </link>
  <link name="link_2_l">
    <visual>
      <geometry>
        <mesh filename="package://motoman_gp25_support/meshes/gp25/visual/link_2_l.dae"/>
      </geometry>
      <material name="">
        <color rgba="0.12941176470588237 0.14901960784313725 0.7490196078431373 1.0"/>
      </material>
    </visual>
    <collision>
      <geometry>
        <mesh filename="package://motoman_gp25_support/meshes/gp25/collision/link_2_l.stl"/>
      </geometry>
    </collision>
  </link>
  <link name="link_3_u">
    <visual>
      <geometry>
        <mesh filename="package://motoman_gp25_support/meshes/gp25/visual/link_3_u.dae"/>
      </geometry>
      <material name="">
        <color rgba="0.12941176470588237 0.14901960784313725 0.7490196078431373 1.0"/>
      </material>
    </visual>
    <collision>
      <geometry>
        <mesh filename="package://motoman_gp25_support/meshes/gp25/collision/link_3_u.stl"/>
      </geometry>
    </collision>
  </link>
  <link name="link_4_r">
    <visual>
      <geometry>
        <mesh filename="package://motoman_gp25_support/meshes/gp25_12/visual/link_4_r.dae"/>
      </geometry>
      <material name="">
        <color rgba="0.12941176470588237 0.14901960784313725 0.7490196078431373 1.0"/>
      </material>
    </visual>
    <collision>
      <geometry>
        <mesh filename="package://motoman_gp25_support/meshes/gp25_12/collision/link_4_r.stl"/>
      </geometry>
    </collision>
  </link>
  <link name="link_5_b">
    <visual>
      <geometry>
        <mesh filename="package://motoman_gp25_support/meshes/gp25/visual/link_5_b.dae"/>
      </geometry>
      <material name="">
        <color rgba="0.12941176470588237 0.14901960784313725 0.7490196078431373 1.0"/>
      </material>
    </visual>
    <collision>
      <geometry>
        <mesh filename="package://motoman_gp25_support/meshes/gp25/collision/link_5_b.stl"/>
      </geometry>
    </collision>
  </link>
  <link name="link_6_t">
    <visual>
      <geometry>
        <mesh filename="package://motoman_gp25_support/meshes/gp25/visual/link_6_t.dae"/>
      </geometry>
      <material name="">
        <color rgba="0.12941176470588237 0.14901960784313725 0.7490196078431373 1.0"/>
      </material>
    </visual>
    <collision>
      <geometry>
        <mesh filename="package://motoman_gp25_support/meshes/gp25/collision/link_6_t.stl"/>
      </geometry>
    </collision>
  </link>
  <!-- end of link list -->
  <!-- joint list -->
  <joint name="joint_1_s" type="revolute">
    <parent link="base_link"/>
    <child link="link_1_s"/>
    <origin rpy="0 0 0" xyz="0 0 0.505"/>
    <axis xyz="0 0 1"/>
    <limit effort="3087" lower="-3.141592653589793" upper="3.141592653589793" velocity="3.6651914291880923"/>
  </joint>
  <joint name="joint_2_l" type="revolute">
    <parent link="link_1_s"/>
    <child link="link_2_l"/>
    <origin rpy="0 0 0" xyz="0.150 0 0"/>
    <axis xyz="0 1 0"/>
    <limit effort="3087" lower="-1.8325957145940461" upper="2.705260340591211" velocity="3.6651914291880923"/>
  </joint>
  <joint name="joint_3_u" type="revolute">
    <parent link="link_2_l"/>
    <child link="link_3_u"/>
    <origin rpy="0 0 0" xyz="0 0 0.760"/>
    <axis xyz="0 -1 0"/>
    <limit effort="926.1" lower="-1.5009831567151235" upper="2.792526803190927" velocity="3.839724354387525"/>
  </joint>
  <joint name="joint_4_r" type="revolute">
    <parent link="link_3_u"/>
    <child link="link_4_r"/>
    <origin rpy="0 0 0" xyz="1.082 0 0.200"/>
    <axis xyz="-1 0 0"/>
    <limit effort="78.4" lower="-3.490658503988659" upper="3.490658503988659" velocity="7.592182246175334"/>
  </joint>
  <joint name="joint_5_b" type="revolute">
    <parent link="link_4_r"/>
    <child link="link_5_b"/>
    <origin rpy="0 0 0" xyz="0 0 0"/>
    <axis xyz="0 -1 0"/>
    <limit effort="67.0" lower="-2.6179938779914944" upper="2.6179938779914944" velocity="7.592182246175334"/>
  </joint>
  <joint name="joint_6_t" type="revolute">
    <parent link="link_5_b"/>
    <child link="link_6_t"/>
    <origin rpy="0 0 0" xyz="0 0 0"/>
    <axis xyz="-1 0 0"/>
    <limit effort="33.3" lower="-7.941248096574199" upper="7.941248096574199" velocity="12.217304763960307"/>
  </joint>
  <!-- end of joint list -->
  <!-- ROS-Industrial 'flange' frame: attachment point for EEF models -->
  <link name="flange"/>
  <joint name="joint_6_t-flange" type="fixed">
    <origin rpy="0 0 0" xyz="0.100 0 0"/>
    <parent link="link_6_t"/>
    <child link="flange"/>
  </joint>
  <!-- ROS-Industrial 'tool0' frame: all-zeros tool frame -->
  <link name="tool0"/>
  <joint name="flange-tool0" type="fixed">
    <origin rpy="3.141592653589793 -1.5707963267948966 0" xyz="0 0 0"/>
    <parent link="flange"/>
    <child link="tool0"/>
  </joint>
  <!-- ROS base_link to Robot Manufacturer World Coordinates transform -->
  <link name="base"/>
  <joint name="base_link-base" type="fixed">
    <origin rpy="0 0 0" xyz="0 0 0.505"/>
    <parent link="base_link"/>
    <child link="base"/>
  </joint>
</robot>
